[2025-01-04T13:40:07.031+0000] {taskinstance.py:1956} INFO - Dependencies all met for dep_context=non-requeueable deps ti=<TaskInstance: insert_data.md_currency_d manual__2025-01-04T13:34:59.232372+00:00 [queued]>
[2025-01-04T13:40:07.043+0000] {taskinstance.py:1956} INFO - Dependencies all met for dep_context=requeueable deps ti=<TaskInstance: insert_data.md_currency_d manual__2025-01-04T13:34:59.232372+00:00 [queued]>
[2025-01-04T13:40:07.043+0000] {taskinstance.py:2170} INFO - Starting attempt 2 of 3
[2025-01-04T13:40:07.060+0000] {taskinstance.py:2191} INFO - Executing <Task(PythonOperator): md_currency_d> on 2025-01-04 13:34:59.232372+00:00
[2025-01-04T13:40:07.067+0000] {standard_task_runner.py:60} INFO - Started process 429 to run task
[2025-01-04T13:40:07.071+0000] {standard_task_runner.py:87} INFO - Running: ['***', 'tasks', 'run', 'insert_data', 'md_currency_d', 'manual__2025-01-04T13:34:59.232372+00:00', '--job-id', '1789', '--raw', '--subdir', 'DAGS_FOLDER/insert_data.py', '--cfg-path', '/tmp/tmpsbxk2dqx']
[2025-01-04T13:40:07.074+0000] {standard_task_runner.py:88} INFO - Job 1789: Subtask md_currency_d
[2025-01-04T13:40:07.296+0000] {task_command.py:423} INFO - Running <TaskInstance: insert_data.md_currency_d manual__2025-01-04T13:34:59.232372+00:00 [running]> on host 8e43a3616b86
[2025-01-04T13:40:07.379+0000] {taskinstance.py:2480} INFO - Exporting env vars: AIRFLOW_CTX_DAG_OWNER='abershits' AIRFLOW_CTX_DAG_ID='insert_data' AIRFLOW_CTX_TASK_ID='md_currency_d' AIRFLOW_CTX_EXECUTION_DATE='2025-01-04T13:34:59.232372+00:00' AIRFLOW_CTX_TRY_NUMBER='2' AIRFLOW_CTX_DAG_RUN_ID='manual__2025-01-04T13:34:59.232372+00:00'
[2025-01-04T13:40:12.401+0000] {taskinstance.py:2698} ERROR - Task failed with exception
Traceback (most recent call last):
  File "/home/airflow/.local/lib/python3.8/site-packages/airflow/models/taskinstance.py", line 433, in _execute_task
    result = execute_callable(context=context, **execute_callable_kwargs)
  File "/home/airflow/.local/lib/python3.8/site-packages/airflow/operators/python.py", line 199, in execute
    return_value = self.execute_callable()
  File "/home/airflow/.local/lib/python3.8/site-packages/airflow/operators/python.py", line 216, in execute_callable
    return self.python_callable(*self.op_args, **self.op_kwargs)
  File "/opt/airflow/dags/insert_data.py", line 36, in insert_data
    df['currency_code'] = df['currency_code'].fillna(None).astype(int).astype(str)
  File "/home/airflow/.local/lib/python3.8/site-packages/pandas/core/series.py", line 5145, in fillna
    return super().fillna(
  File "/home/airflow/.local/lib/python3.8/site-packages/pandas/core/generic.py", line 6859, in fillna
    value, method = validate_fillna_kwargs(value, method)
  File "/home/airflow/.local/lib/python3.8/site-packages/pandas/util/_validators.py", line 288, in validate_fillna_kwargs
    raise ValueError("Must specify a fill 'value' or 'method'.")
ValueError: Must specify a fill 'value' or 'method'.
[2025-01-04T13:40:12.418+0000] {taskinstance.py:1138} INFO - Marking task as UP_FOR_RETRY. dag_id=insert_data, task_id=md_currency_d, execution_date=20250104T133459, start_date=20250104T134007, end_date=20250104T134012
[2025-01-04T13:40:12.456+0000] {standard_task_runner.py:107} ERROR - Failed to execute job 1789 for task md_currency_d (Must specify a fill 'value' or 'method'.; 429)
[2025-01-04T13:40:12.496+0000] {local_task_job_runner.py:234} INFO - Task exited with return code 1
[2025-01-04T13:40:12.518+0000] {taskinstance.py:3280} INFO - 0 downstream tasks scheduled from follow-on schedule check
