[2025-01-04T13:33:47.039+0000] {taskinstance.py:1956} INFO - Dependencies all met for dep_context=non-requeueable deps ti=<TaskInstance: insert_data.md_currency_d manual__2025-01-04T13:23:32.460853+00:00 [queued]>
[2025-01-04T13:33:47.049+0000] {taskinstance.py:1956} INFO - Dependencies all met for dep_context=requeueable deps ti=<TaskInstance: insert_data.md_currency_d manual__2025-01-04T13:23:32.460853+00:00 [queued]>
[2025-01-04T13:33:47.050+0000] {taskinstance.py:2170} INFO - Starting attempt 3 of 3
[2025-01-04T13:33:47.065+0000] {taskinstance.py:2191} INFO - Executing <Task(PythonOperator): md_currency_d> on 2025-01-04 13:23:32.460853+00:00
[2025-01-04T13:33:47.074+0000] {standard_task_runner.py:60} INFO - Started process 315 to run task
[2025-01-04T13:33:47.078+0000] {standard_task_runner.py:87} INFO - Running: ['***', 'tasks', 'run', 'insert_data', 'md_currency_d', 'manual__2025-01-04T13:23:32.460853+00:00', '--job-id', '1783', '--raw', '--subdir', 'DAGS_FOLDER/insert_data.py', '--cfg-path', '/tmp/tmpiuxi95on']
[2025-01-04T13:33:47.083+0000] {standard_task_runner.py:88} INFO - Job 1783: Subtask md_currency_d
[2025-01-04T13:33:47.311+0000] {task_command.py:423} INFO - Running <TaskInstance: insert_data.md_currency_d manual__2025-01-04T13:23:32.460853+00:00 [running]> on host 8e43a3616b86
[2025-01-04T13:33:47.393+0000] {taskinstance.py:2480} INFO - Exporting env vars: AIRFLOW_CTX_DAG_OWNER='abershits' AIRFLOW_CTX_DAG_ID='insert_data' AIRFLOW_CTX_TASK_ID='md_currency_d' AIRFLOW_CTX_EXECUTION_DATE='2025-01-04T13:23:32.460853+00:00' AIRFLOW_CTX_TRY_NUMBER='3' AIRFLOW_CTX_DAG_RUN_ID='manual__2025-01-04T13:23:32.460853+00:00'
[2025-01-04T13:33:52.425+0000] {base.py:83} INFO - Using connection ID 'postgres_db' for task execution.
[2025-01-04T13:33:52.451+0000] {taskinstance.py:2698} ERROR - Task failed with exception
Traceback (most recent call last):
  File "/home/airflow/.local/lib/python3.8/site-packages/sqlalchemy/engine/base.py", line 1910, in _execute_context
    self.dialect.do_execute(
  File "/home/airflow/.local/lib/python3.8/site-packages/sqlalchemy/engine/default.py", line 736, in do_execute
    cursor.execute(statement, parameters)
psycopg2.errors.StringDataRightTruncation: value too long for type character varying(3)


The above exception was the direct cause of the following exception:

Traceback (most recent call last):
  File "/home/airflow/.local/lib/python3.8/site-packages/airflow/models/taskinstance.py", line 433, in _execute_task
    result = execute_callable(context=context, **execute_callable_kwargs)
  File "/home/airflow/.local/lib/python3.8/site-packages/airflow/operators/python.py", line 199, in execute
    return_value = self.execute_callable()
  File "/home/airflow/.local/lib/python3.8/site-packages/airflow/operators/python.py", line 216, in execute_callable
    return self.python_callable(*self.op_args, **self.op_kwargs)
  File "/opt/airflow/dags/insert_data.py", line 64, in insert_data
    conn.execute(insert_query, tuple(row))
  File "/home/airflow/.local/lib/python3.8/site-packages/sqlalchemy/engine/base.py", line 1370, in execute
    return self._exec_driver_sql(
  File "/home/airflow/.local/lib/python3.8/site-packages/sqlalchemy/engine/base.py", line 1674, in _exec_driver_sql
    ret = self._execute_context(
  File "/home/airflow/.local/lib/python3.8/site-packages/sqlalchemy/engine/base.py", line 1953, in _execute_context
    self._handle_dbapi_exception(
  File "/home/airflow/.local/lib/python3.8/site-packages/sqlalchemy/engine/base.py", line 2134, in _handle_dbapi_exception
    util.raise_(
  File "/home/airflow/.local/lib/python3.8/site-packages/sqlalchemy/util/compat.py", line 211, in raise_
    raise exception
  File "/home/airflow/.local/lib/python3.8/site-packages/sqlalchemy/engine/base.py", line 1910, in _execute_context
    self.dialect.do_execute(
  File "/home/airflow/.local/lib/python3.8/site-packages/sqlalchemy/engine/default.py", line 736, in do_execute
    cursor.execute(statement, parameters)
sqlalchemy.exc.DataError: (psycopg2.errors.StringDataRightTruncation) value too long for type character varying(3)

[SQL: 
                INSERT INTO "ds".md_currency_d (currency_rk, data_actual_date, data_actual_end_date, currency_code, code_iso_char)
                VALUES (%s, %s, %s, %s, %s)
                ON CONFLICT (currency_rk, data_actual_date)
                DO UPDATE SET data_actual_end_date = EXCLUDED.data_actual_end_date, currency_code = EXCLUDED.currency_code, code_iso_char = EXCLUDED.code_iso_char
                RETURNING *;
                ]
[parameters: (50, Timestamp('2017-05-11 00:00:00'), Timestamp('2050-12-31 00:00:00'), 356.0, 'INR')]
(Background on this error at: https://sqlalche.me/e/14/9h9h)
[2025-01-04T13:33:52.461+0000] {taskinstance.py:1138} INFO - Marking task as FAILED. dag_id=insert_data, task_id=md_currency_d, execution_date=20250104T132332, start_date=20250104T133347, end_date=20250104T133352
[2025-01-04T13:33:52.476+0000] {standard_task_runner.py:107} ERROR - Failed to execute job 1783 for task md_currency_d ((psycopg2.errors.StringDataRightTruncation) value too long for type character varying(3)

[SQL: 
                INSERT INTO "ds".md_currency_d (currency_rk, data_actual_date, data_actual_end_date, currency_code, code_iso_char)
                VALUES (%s, %s, %s, %s, %s)
                ON CONFLICT (currency_rk, data_actual_date)
                DO UPDATE SET data_actual_end_date = EXCLUDED.data_actual_end_date, currency_code = EXCLUDED.currency_code, code_iso_char = EXCLUDED.code_iso_char
                RETURNING *;
                ]
[parameters: (50, Timestamp('2017-05-11 00:00:00'), Timestamp('2050-12-31 00:00:00'), 356.0, 'INR')]
(Background on this error at: https://sqlalche.me/e/14/9h9h); 315)
[2025-01-04T13:33:52.502+0000] {local_task_job_runner.py:234} INFO - Task exited with return code 1
[2025-01-04T13:33:52.523+0000] {taskinstance.py:3280} INFO - 0 downstream tasks scheduled from follow-on schedule check
